Workbook

Sheet README
A1: Rainmaker Remodel — Cold Email Analytics
A2: How this sheet works
A3: READ-ONLY SYSTEM | B3: This sheet pulls data from SmartLead and GHL via GET requests only. No data in SmartLead or GHL is ever modified.
A5: Tab 1 — Config | B5: Stores the last sync timestamp and sync status. Your custom sync script reads/writes to this tab.
A6: Tab 2 — Raw SmartLead Replies | B6: One row per replied lead. Contains the actual reply text, SL category (Interested/Uninterested/etc), and sequence step.
A7: Tab 3 — Raw SmartLead Stats | B7: Aggregate totals per campaign (sent, opened, replied, bounced). Used for calculating reply rates.
A8: Tab 4 — Raw SmartLead Sequences | B8: The actual copy (subject lines, body, CTAs) for every email step in every campaign.
A9: Tab 5 — Raw GHL Data | B9: One row per contact. Contains stage-entry timestamps for each GHL pipeline stage.
A10: Tab 6 — Campaign Overview | B10: Auto-calculated aggregate metrics per campaign (ALL TIME). Every cell is a formula.
A11: Tab 7 — Time Range Views | B11: Same metrics as Overview but filtered by Past 7 Days, Past 30 Days, Past 90 Days, All Time.
A13: GHL Pipeline Stages | B13: Inbound Reply Engaged → Awaiting Response → Day 1 Follow-Up → Day 2 Follow-Up → Call Proposed → Call Booked
A15: SmartLead Reply Categories | B15: Interested, Uninterested, Wrong Person, Out of Office, Do Not Contact
A17: Adding new analysis later | B17: You can add new tabs or columns anytime without disrupting existing data. The raw data tabs just get appended to.
A19: Import to Google Sheets | B19: Upload this .xlsx to Google Drive → Right-click → Open with Google Sheets → File → Save as Google Sheets.

Sheet Config
A1: Rainmaker Remodel — Cold Email Analytics
A3: Field | B3: Value
A4: Client Name | B4: Rainmaker Remodel
A5: last_synced_at | B5: (will be updated by sync script)
A6: smartlead_last_sync | B6: (will be updated by sync script)
A7: ghl_last_sync | B7: (will be updated by sync script)
A8: sync_status | B8: Pending initial sync
A9: next_scheduled_sync | B9: (will be updated by sync script)
A10: sync_frequency | B10: Daily
A11: timezone | B11: America/New_York

Sheet Raw SmartLead Replies
A1: Campaign ID | B1: Campaign Name | C1: Lead Email | D1: Lead Name | E1: Reply Text | F1: Reply Date | G1: SL Category | H1: Sequence Step | I1: Sync Date
A2: 3134980 | B2: 60 Day Ads - Bathroom Renovations (USA) | C2: john@example.com | D2: John Smith | E2: Yeah interested, send more info | F2: 2026-04-10 | G2: Interested | H2: 1 | I2: 2026-04-10
A3: (sample row above — delete once real data syncs in)

Sheet Raw SmartLead Stats
A1: Campaign ID | B1: Campaign Name | C1: Total Sent | D1: Total Replied | E1: Reply Rate | F1: Positive Reply Rate | G1: Total Bounced | H1: Start Date | I1: Sync Date
A2: 3134980 | B2: 60 Day Ads - Bathroom Renovations (USA) | C2: 0 | D2: 0 | G2: 0
A3: 3134858 | B3: 60 Day Ads - General Construction USA (Tulsa, Tampa, Cincinnati) | C3: 0 | D3: 0 | G3: 0
A4: 3072412 | B4: 60 Day Ads - Kitchen Renovators (USA) | C4: 0 | D4: 0 | G4: 0
A5: 3043415 | B5: 60 Day Ads Offer - USA (LA, Detroit, Colorado Springs) - copy | C5: 0 | D5: 0 | G5: 0
A6: 2978732 | B6: Huge USA Lead List - 60 Day Ads Offer (Xander) | C6: 0 | D6: 0 | G6: 0

Sheet Raw SmartLead Sequences
A1: Campaign ID | B1: Campaign Name | C1: Step Number | D1: Subject Line | E1: Body Copy | F1: Delay Days | G1: Sync Date

Sheet Raw GHL Data
A1: Contact Name | B1: Email | C1: Campaign ID | D1: Campaign Name | E1: Entered Call Proposed At | F1: Entered Day 1 Follow-Up At | G1: Entered Day 2 Follow-Up At | H1: Entered Call Booked At | I1: Current Stage | J1: Sync Date

Sheet Campaign Overview
A1: Campaign Overview — All Time
A2: Campaign ID | B2: Campaign Name | C2: Total Sent | D2: Total Replied | E2: Reply Rate | F2: Positive Reply Rate | G2: Call Proposed | H2: Day 1 Follow-Up | I2: Day 2 Follow-Up | J2: Calls Booked | K2: Book Rate
A3: 3134980 | B3: 60 Day Ads - Bathroom Renovations (USA) | C3: =IFERROR(VLOOKUP(A3,'Raw SmartLead Stats'!A:G,3,FALSE()),0) -> 0 | D3: =COUNTIF('Raw SmartLead Replies'!A:A,A3) -> 1 | E3: =IFERROR(D3/C3,0) -> 0 | F3: =IFERROR(COUNTIFS('Raw SmartLead Replies'!A:A,A3,'Raw SmartLead Replies'!G:G,"Interested")/D3,0) -> 1 | G3: =COUNTIFS('Raw GHL Data'!C:C,A3,'Raw GHL Data'!F:F,"<>") -> 0 | H3: =COUNTIFS('Raw GHL Data'!C:C,A3,'Raw GHL Data'!G:G,"<>") -> 0 | I3: =COUNTIFS('Raw GHL Data'!C:C,A3,'Raw GHL Data'!E:E,"<>") -> 0 | J3: =COUNTIFS('Raw GHL Data'!C:C,A3,'Raw GHL Data'!H:H,"<>") -> 0 | K3: =IFERROR(J3/D3,0) -> 0
A4: 3134858 | B4: 60 Day Ads - General Construction USA (Tulsa, Tampa, Cincinnati) | C4: =IFERROR(VLOOKUP(A4,'Raw SmartLead Stats'!A:G,3,FALSE()),0) -> 0 | D4: =COUNTIF('Raw SmartLead Replies'!A:A,A4) -> 0 | E4: =IFERROR(D4/C4,0) -> 0 | F4: =IFERROR(COUNTIFS('Raw SmartLead Replies'!A:A,A4,'Raw SmartLead Replies'!G:G,"Interested")/D4,0) -> 0 | G4: =COUNTIFS('Raw GHL Data'!C:C,A4,'Raw GHL Data'!F:F,"<>") -> 0 | H4: =COUNTIFS('Raw GHL Data'!C:C,A4,'Raw GHL Data'!G:G,"<>") -> 0 | I4: =COUNTIFS('Raw GHL Data'!C:C,A4,'Raw GHL Data'!E:E,"<>") -> 0 | J4: =COUNTIFS('Raw GHL Data'!C:C,A4,'Raw GHL Data'!H:H,"<>") -> 0 | K4: =IFERROR(J4/D4,0) -> 0
A5: 3072412 | B5: 60 Day Ads - Kitchen Renovators (USA) | C5: =IFERROR(VLOOKUP(A5,'Raw SmartLead Stats'!A:G,3,FALSE()),0) -> 0 | D5: =COUNTIF('Raw SmartLead Replies'!A:A,A5) -> 0 | E5: =IFERROR(D5/C5,0) -> 0 | F5: =IFERROR(COUNTIFS('Raw SmartLead Replies'!A:A,A5,'Raw SmartLead Replies'!G:G,"Interested")/D5,0) -> 0 | G5: =COUNTIFS('Raw GHL Data'!C:C,A5,'Raw GHL Data'!F:F,"<>") -> 0 | H5: =COUNTIFS('Raw GHL Data'!C:C,A5,'Raw GHL Data'!G:G,"<>") -> 0 | I5: =COUNTIFS('Raw GHL Data'!C:C,A5,'Raw GHL Data'!E:E,"<>") -> 0 | J5: =COUNTIFS('Raw GHL Data'!C:C,A5,'Raw GHL Data'!H:H,"<>") -> 0 | K5: =IFERROR(J5/D5,0) -> 0
A6: 3043415 | B6: 60 Day Ads Offer - USA (LA, Detroit, Colorado Springs) - copy | C6: =IFERROR(VLOOKUP(A6,'Raw SmartLead Stats'!A:G,3,FALSE()),0) -> 0 | D6: =COUNTIF('Raw SmartLead Replies'!A:A,A6) -> 0 | E6: =IFERROR(D6/C6,0) -> 0 | F6: =IFERROR(COUNTIFS('Raw SmartLead Replies'!A:A,A6,'Raw SmartLead Replies'!G:G,"Interested")/D6,0) -> 0 | G6: =COUNTIFS('Raw GHL Data'!C:C,A6,'Raw GHL Data'!F:F,"<>") -> 0 | H6: =COUNTIFS('Raw GHL Data'!C:C,A6,'Raw GHL Data'!G:G,"<>") -> 0 | I6: =COUNTIFS('Raw GHL Data'!C:C,A6,'Raw GHL Data'!E:E,"<>") -> 0 | J6: =COUNTIFS('Raw GHL Data'!C:C,A6,'Raw GHL Data'!H:H,"<>") -> 0 | K6: =IFERROR(J6/D6,0) -> 0
A7: 2978732 | B7: Huge USA Lead List - 60 Day Ads Offer (Xander) | C7: =IFERROR(VLOOKUP(A7,'Raw SmartLead Stats'!A:G,3,FALSE()),0) -> 0 | D7: =COUNTIF('Raw SmartLead Replies'!A:A,A7) -> 0 | E7: =IFERROR(D7/C7,0) -> 0 | F7: =IFERROR(COUNTIFS('Raw SmartLead Replies'!A:A,A7,'Raw SmartLead Replies'!G:G,"Interested")/D7,0) -> 0 | G7: =COUNTIFS('Raw GHL Data'!C:C,A7,'Raw GHL Data'!F:F,"<>") -> 0 | H7: =COUNTIFS('Raw GHL Data'!C:C,A7,'Raw GHL Data'!G:G,"<>") -> 0 | I7: =COUNTIFS('Raw GHL Data'!C:C,A7,'Raw GHL Data'!E:E,"<>") -> 0 | J7: =COUNTIFS('Raw GHL Data'!C:C,A7,'Raw GHL Data'!H:H,"<>") -> 0 | K7: =IFERROR(J7/D7,0) -> 0

Sheet Time Range Views
A1: Time Range Views — Auto-filtered to only show campaigns with activity
A2: Each section uses Google Sheets' FILTER() function to automatically hide campaigns with zero replies in that period. | K2: ← Calculation blocks (don't edit)
A4: Past 7 Days
A5: Time Range | B5: Campaign ID | C5: Campaign Name | D5: Total Replied | E5: Positive Replies | F5: Call Proposed | G5: Call Booked | H5: Book Rate
A6: =IFERROR(arrayformula(IF(LEN(B6:B255),"Past 7 Days","")),"") | B6: =IFERROR(filter({K7:K256,L7:L256,M7:M256,N7:N256,O7:O256,P7:P256,Q7:Q256},M7:M256>0,K7:K256<>""),"(no campaigns with activity in this period)") -> #N/A | K6: Campaign ID | L6: Campaign Name | M6: Total Replied | N6: Positive Replies | O6: Call Proposed | P6: Call Booked | Q6: Book Rate
K7: =IF('Campaign Overview'!A3="","",'Campaign Overview'!A3) -> 3134980 | L7: =IF('Campaign Overview'!A3="","",'Campaign Overview'!B3) -> 60 Day Ads - Bathroom Renovations (USA) | M7: =IF('Campaign Overview'!A3="","",COUNTIFS('Raw SmartLead Replies'!A:A,'Campaign Overview'!A3,'Raw SmartLead Replies'!F:F,">="&TODAY()-7)) -> 0 | N7: =IF('Campaign Overview'!A3="","",COUNTIFS('Raw SmartLead Replies'!A:A,'Campaign Overview'!A3,'Raw SmartLead Replies'!G:G,"Interested",'Raw SmartLead Replies'!F:F,">="&TODAY()-7)) -> 0 | O7: =IF('Campaign Overview'!A3="","",COUNTIFS('Raw GHL Data'!C:C,'Campaign Overview'!A3,'Raw GHL Data'!E:E,">="&TODAY()-7)) -> 0 | P7: =IF('Campaign Overview'!A3="","",COUNTIFS('Raw GHL Data'!C:C,'Campaign Overview'!A3,'Raw GHL Data'!H:H,">="&TODAY()-7)) -> 0 | Q7: =IF(OR('Campaign Overview'!A3="",M7=0),"",P7/M7)
K8: =IF('Campaign Overview'!A4="","",'Campaign Overview'!A4) -> 3134858 | L8: =IF('Campaign Overview'!A4="","",'Campaign Overview'!B4) -> 60 Day Ads - General Construction USA (Tulsa, Tampa, Cincinnati) | M8: =IF('Campaign Overview'!A4="","",COUNTIFS('Raw SmartLead Replies'!A:A,'Campaign Overview'!A4,'Raw SmartLead Replies'!F:F,">="&TODAY()-7)) -> 0 | N8: =IF('Campaign Overview'!A4="","",COUNTIFS('Raw SmartLead Replies'!A:A,'Campaign Overview'!A4,'Raw SmartLead Replies'!G:G,"Interested",'Raw SmartLead Replies'!F:F,">="&TODAY()-7)) -> 0 | O8: =IF('Campaign Overview'!A4="","",COUNTIFS('Raw GHL Data'!C:C,'Campaign Overview'!A4,'Raw GHL Data'!E:E,">="&TODAY()-7)) -> 0 | P8: =IF('Campaign Overview'!A4="","",COUNTIFS('Raw GHL Data'!C:C,'Campaign Overview'!A4,'Raw GHL Data'!H:H,">="&TODAY()-7)) -> 0 | Q8: =IF(OR('Campaign Overview'!A4="",M8=0),"",P8/M8)
K9: =IF('Campaign Overview'!A5="","",'Campaign Overview'!A5) -> 3072412 | L9: =IF('Campaign Overview'!A5="","",'Campaign Overview'!B5) -> 60 Day Ads - Kitchen Renovators (USA) | M9: =IF('Campaign Overview'!A5="","",COUNTIFS('Raw SmartLead Replies'!A:A,'Campaign Overview'!A5,'Raw SmartLead Replies'!F:F,">="&TODAY()-7)) -> 0 | N9: =IF('Campaign Overview'!A5="","",COUNTIFS('Raw SmartLead Replies'!A:A,'Campaign Overview'!A5,'Raw SmartLead Replies'!G:G,"Interested",'Raw SmartLead Replies'!F:F,">="&TODAY()-7)) -> 0 | O9: =IF('Campaign Overview'!A5="","",COUNTIFS('Raw GHL Data'!C:C,'Campaign Overview'!A5,'Raw GHL Data'!E:E,">="&TODAY()-7)) -> 0 | P9: =IF('Campaign Overview'!A5="","",COUNTIFS('Raw GHL Data'!C:C,'Campaign Overview'!A5,'Raw GHL Data'!H:H,">="&TODAY()-7)) -> 0 | Q9: =IF(OR('Campaign Overview'!A5="",M9=0),"",P9/M9)
K10: =IF('Campaign Overview'!A6="","",'Campaign Overview'!A6) -> 3043415 | L10: =IF('Campaign Overview'!A6="","",'Campaign Overview'!B6) -> 60 Day Ads Offer - USA (LA, Detroit, Colorado Springs) - copy | M10: =IF('Campaign Overview'!A6="","",COUNTIFS('Raw SmartLead Replies'!A:A,'Campaign Overview'!A6,'Raw SmartLead Replies'!F:F,">="&TODAY()-7)) -> 0 | N10: =IF('Campaign Overview'!A6="","",COUNTIFS('Raw SmartLead Replies'!A:A,'Campaign Overview'!A6,'Raw SmartLead Replies'!G:G,"Interested",'Raw SmartLead Replies'!F:F,">="&TODAY()-7)) -> 0 | O10: =IF('Campaign Overview'!A6="","",COUNTIFS('Raw GHL Data'!C:C,'Campaign Overview'!A6,'Raw GHL Data'!E:E,">="&TODAY()-7)) -> 0 | P10: =IF('Campaign Overview'!A6="","",COUNTIFS('Raw GHL Data'!C:C,'Campaign Overview'!A6,'Raw GHL Data'!H:H,">="&TODAY()-7)) -> 0 | Q10: =IF(OR('Campaign Overview'!A6="",M10=0),"",P10/M10)
K11: =IF('Campaign Overview'!A7="","",'Campaign Overview'!A7) -> 2978732 | L11: =IF('Campaign Overview'!A7="","",'Campaign Overview'!B7) -> Huge USA Lead List - 60 Day Ads Offer (Xander) | M11: =IF('Campaign Overview'!A7="","",COUNTIFS('Raw SmartLead Replies'!A:A,'Campaign Overview'!A7,'Raw SmartLead Replies'!F:F,">="&TODAY()-7)) -> 0 | N11: =IF('Campaign Overview'!A7="","",COUNTIFS('Raw SmartLead Replies'!A:A,'Campaign Overview'!A7,'Raw SmartLead Replies'!G:G,"Interested",'Raw SmartLead Replies'!F:F,">="&TODAY()-7)) -> 0 | O11: =IF('Campaign Overview'!A7="","",COUNTIFS('Raw GHL Data'!C:C,'Campaign Overview'!A7,'Raw GHL Data'!E:E,">="&TODAY()-7)) -> 0 | P11: =IF('Campaign Overview'!A7="","",COUNTIFS('Raw GHL Data'!C:C,'Campaign Overview'!A7,'Raw GHL Data'!H:H,">="&TODAY()-7)) -> 0 | Q11: =IF(OR('Campaign Overview'!A7="",M11=0),"",P11/M11)
K12: =IF('Campaign Overview'!A8="","",'Campaign Overview'!A8) | L12: =IF('Campaign Overview'!A8="","",'Campaign Overview'!B8) | M12: =IF('Campaign Overview'!A8="","",COUNTIFS('Raw SmartLead Replies'!A:A,'Campaign Overview'!A8,'Raw SmartLead Replies'!F:F,">="&TODAY()-7)) | N12: =IF('Campaign Overview'!A8="","",COUNTIFS('Raw SmartLead Replies'!A:A,'Campaign Overview'!A8,'Raw SmartLead Replies'!G:G,"Interested",'Raw SmartLead Replies'!F:F,">="&TODAY()-7)) | O12: =IF('Campaign Overview'!A8="","",COUNTIFS('Raw GHL Data'!C:C,'Campaign Overview'!A8,'Raw GHL Data'!E:E,">="&TODAY()-7)) | P12: =IF('Campaign Overview'!A8="","",COUNTIFS('Raw GHL Data'!C:C,'Campaign Overview'!A8,'Raw GHL Data'!H:H,">="&TODAY()-7)) | Q12: =IF(OR('Campaign Overview'!A8="",M12=0),"",P12/M12)
K13: =IF('Campaign Overview'!A9="","",'Campaign Overview'!A9) | L13: =IF('Campaign Overview'!A9="","",'Campaign Overview'!B9) | M13: =IF('Campaign Overview'!A9="","",COUNTIFS('Raw SmartLead Replies'!A:A,'Campaign Overview'!A9,'Raw SmartLead Replies'!F:F,">="&TODAY()-7)) | N13: =IF('Campaign Overview'!A9="","",COUNTIFS('Raw SmartLead Replies'!A:A,'Campaign Overview'!A9,'Raw SmartLead Replies'!G:G,"Interested",'Raw SmartLead Replies'!F:F,">="&TODAY()-7)) | O13: =IF('Campaign Overview'!A9="","",COUNTIFS('Raw GHL Data'!C:C,'Campaign Overview'!A9,'Raw GHL Data'!E:E,">="&TODAY()-7)) | P13: =IF('Campaign Overview'!A9="","",COUNTIFS('Raw GHL Data'!C:C,'Campaign Overview'!A9,'Raw GHL Data'!H:H,">="&TODAY()-7)) | Q13: =IF(OR('Campaign Overview'!A9="",M13=0),"",P13/M13)
K14: =IF('Campaign Overview'!A10="","",'Campaign Overview'!A10) | L14: =IF('Campaign Overview'!A10="","",'Campaign Overview'!B10) | M14: =IF('Campaign Overview'!A10="","",COUNTIFS('Raw SmartLead Replies'!A:A,'Campaign Overview'!A10,'Raw SmartLead Replies'!F:F,">="&TODAY()-7)) | N14: =IF('Campaign Overview'!A10="","",COUNTIFS('Raw SmartLead Replies'!A:A,'Campaign Overview'!A10,'Raw SmartLead Replies'!G:G,"Interested",'Raw SmartLead Replies'!F:F,">="&TODAY()-7)) | O14: =IF('Campaign Overview'!A10="","",COUNTIFS('Raw GHL Data'!C:C,'Campaign Overview'!A10,'Raw GHL Data'!E:E,">="&TODAY()-7)) | P14: =IF('Campaign Overview'!A10="","",COUNTIFS('Raw GHL Data'!C:C,'Campaign Overview'!A10,'Raw GHL Data'!H:H,">="&TODAY()-7)) | Q14: =IF(OR('Campaign Overview'!A10="",M14=0),"",P14/M14)
K15: =IF('Campaign Overview'!A11="","",'Campaign Overview'!A11) | L15: =IF('Campaign Overview'!A11="","",'Campaign Overview'!B11) | M15: =IF('Campaign Overview'!A11="","",COUNTIFS('Raw SmartLead Replies'!A:A,'Campaign Overview'!A11,'Raw SmartLead Replies'!F:F,">="&TODAY()-7)) | N15: =IF('Campaign Overview'!A11="","",COUNTIFS('Raw SmartLead Replies'!A:A,'Campaign Overview'!A11,'Raw SmartLead Replies'!G:G,"Interested",'Raw SmartLead Replies'!F:F,">="&TODAY()-7)) | O15: =IF('Campaign Overview'!A11="","",COUNTIFS('Raw GHL Data'!C:C,'Campaign Overview'!A11,'Raw GHL Data'!E:E,">="&TODAY()-7)) | P15: =IF('Campaign Overview'!A11="","",COUNTIFS('Raw GHL Data'!C:C,'Campaign Overview'!A11,'Raw GHL Data'!H:H,">="&TODAY()-7)) | Q15: =IF(OR('Campaign Overview'!A11="",M15=0),"",P15/M15)
K16: =IF('Campaign Overview'!A12="","",'Campaign Overview'!A12) | L16: =IF('Campaign Overview'!A12="","",'Campaign Overview'!B12) | M16: =IF('Campaign Overview'!A12="","",COUNTIFS('Raw SmartLead Replies'!A:A,'Campaign Overview'!A12,'Raw SmartLead Replies'!F:F,">="&TODAY()-7)) | N16: =IF('Campaign Overview'!A12="","",COUNTIFS('Raw SmartLead Replies'!A:A,'Campaign Overview'!A12,'Raw SmartLead Replies'!G:G,"Interested",'Raw SmartLead Replies'!F:F,">="&TODAY()-7)) | O16: =IF('Campaign Overview'!A12="","",COUNTIFS('Raw GHL Data'!C:C,'Campaign Overview'!A12,'Raw GHL Data'!E:E,">="&TODAY()-7)) | P16: =IF('Campaign Overview'!A12="","",COUNTIFS('Raw GHL Data'!C:C,'Campaign Overview'!A12,'Raw GHL Data'!H:H,">="&TODAY()-7)) | Q16: =IF(OR('Campaign Overview'!A12="",M16=0),"",P16/M16)
K17: =IF('Campaign Overview'!A13="","",'Campaign Overview'!A13) | L17: =IF('Campaign Overview'!A13="","",'Campaign Overview'!B13) | M17: =IF('Campaign Overview'!A13="","",COUNTIFS('Raw SmartLead Replies'!A:A,'Campaign Overview'!A13,'Raw SmartLead Replies'!F:F,">="&TODAY()-7)) | N17: =IF('Campaign Overview'!A13="","",COUNTIFS('Raw SmartLead Replies'!A:A,'Campaign Overview'!A13,'Raw SmartLead Replies'!G:G,"Interested",'Raw SmartLead Replies'!F:F,">="&TODAY()-7)) | O17: =IF('Campaign Overview'!A13="","",COUNTIFS('Raw GHL Data'!C:C,'Campaign Overview'!A13,'Raw GHL Data'!E:E,">="&TODAY()-7)) | P17: =IF('Campaign Overview'!A13="","",COUNTIFS('Raw GHL Data'!C:C,'Campaign Overview'!A13,'Raw GHL Data'!H:H,">="&TODAY()-7)) | Q17: =IF(OR('Campaign Overview'!A13="",M17=0),"",P17/M17)
K18: =IF('Campaign Overview'!A14="","",'Campaign Overview'!A14) | L18: =IF('Campaign Overview'!A14="","",'Campaign Overview'!B14) | M18: =IF('Campaign Overview'!A14="","",COUNTIFS('Raw SmartLead Replies'!A:A,'Campaign Overview'!A14,'Raw SmartLead Replies'!F:F,">="&TODAY()-7)) | N18: =IF('Campaign Overview'!A14="","",COUNTIFS('Raw SmartLead Replies'!A:A,'Campaign Overview'!A14,'Raw SmartLead Replies'!G:G,"Interested",'Raw SmartLead Replies'!F:F,">="&TODAY()-7)) | O18: =IF('Campaign Overview'!A14="","",COUNTIFS('Raw GHL Data'!C:C,'Campaign Overview'!A14,'Raw GHL Data'!E:E,">="&TODAY()-7)) | P18: =IF('Campaign Overview'!A14="","",COUNTIFS('Raw GHL Data'!C:C,'Campaign Overview'!A14,'Raw GHL Data'!H:H,">="&TODAY()-7)) | Q18: =IF(OR('Campaign Overview'!A14="",M18=0),"",P18/M18)
... K55: =IF('Campaign Overview'!A51="","",'Campaign Overview'!A51) | L55: =IF('Campaign Overview'!A51="","",'Campaign Overview'!B51) | M55: =IF('Campaign Overview'!A51="","",COUNTIFS('Raw SmartLead Replies'!A:A,'Campaign Overview'!A51,'Raw SmartLead Replies'!F:F,">="&TODAY()-7)) | N55: =IF('Campaign Overview'!A51="","",COUNTIFS('Raw SmartLead Replies'!A:A,'Campaign Overview'!A51,'Raw SmartLead Replies'!G:G,"Interested",'Raw SmartLead Replies'!F:F,">="&TODAY()-7)) | O55: =IF('Campaign Overview'!A51="","",COUNTIFS('Raw GHL Data'!C:C,'Campaign Overview'!A51,'Raw GHL Data'!E:E,">="&TODAY()-7)) | P55: =IF('Campaign Overview'!A51="","",COUNTIFS('Raw GHL Data'!C:C,'Campaign Overview'!A51,'Raw GHL Data'!H:H,">="&TODAY()-7)) | Q55: =IF(OR('Campaign Overview'!A51="",M55=0),"",P55/M55)
A56: Past 30 Days | K56: =IF('Campaign Overview'!A52="","",'Campaign Overview'!A52) | L56: =IF('Campaign Overview'!A52="","",'Campaign Overview'!B52) | M56: =IF('Campaign Overview'!A52="","",COUNTIFS('Raw SmartLead Replies'!A:A,'Campaign Overview'!A52,'Raw SmartLead Replies'!F:F,">="&TODAY()-7)) | N56: =IF('Campaign Overview'!A52="","",COUNTIFS('Raw SmartLead Replies'!A:A,'Campaign Overview'!A52,'Raw SmartLead Replies'!G:G,"Interested",'Raw SmartLead Replies'!F:F,">="&TODAY()-7)) | O56: =IF('Campaign Overview'!A52="","",COUNTIFS('Raw GHL Data'!C:C,'Campaign Overview'!A52,'Raw GHL Data'!E:E,">="&TODAY()-7)) | P56: =IF('Campaign Overview'!A52="","",COUNTIFS('Raw GHL Data'!C:C,'Campaign Overview'!A52,'Raw GHL Data'!H:H,">="&TODAY()-7)) | Q56: =IF(OR('Campaign Overview'!A52="",M56=0),"",P56/M56)
A57: Time Range | B57: Campaign ID | C57: Campaign Name | D57: Total Replied | E57: Positive Replies | F57: Call Proposed | G57: Call Booked | H57: Book Rate | K57: =IF('Campaign Overview'!A53="","",'Campaign Overview'!A53) | L57: =IF('Campaign Overview'!A53="","",'Campaign Overview'!B53) | M57: =IF('Campaign Overview'!A53="","",COUNTIFS('Raw SmartLead Replies'!A:A,'Campaign Overview'!A53,'Raw SmartLead Replies'!F:F,">="&TODAY()-7)) | N57: =IF('Campaign Overview'!A53="","",COUNTIFS('Raw SmartLead Replies'!A:A,'Campaign Overview'!A53,'Raw SmartLead Replies'!G:G,"Interested",'Raw SmartLead Replies'!F:F,">="&TODAY()-7)) | O57: =IF('Campaign Overview'!A53="","",COUNTIFS('Raw GHL Data'!C:C,'Campaign Overview'!A53,'Raw GHL Data'!E:E,">="&TODAY()-7)) | P57: =IF('Campaign Overview'!A53="","",COUNTIFS('Raw GHL Data'!C:C,'Campaign Overview'!A53,'Raw GHL Data'!H:H,">="&TODAY()-7)) | Q57: =IF(OR('Campaign Overview'!A53="",M57=0),"",P57/M57)
A58: =IFERROR(arrayformula(IF(LEN(B58:B307),"Past 30 Days","")),"") | B58: =IFERROR(filter({K59:K308,L59:L308,M59:M308,N59:N308,O59:O308,P59:P308,Q59:Q308},M59:M308>0,K59:K308<>""),"(no campaigns with activity in this period)") -> #N/A | K58: Campaign ID | L58: Campaign Name | M58: Total Replied | N58: Positive Replies | O58: Call Proposed | P58: Call Booked | Q58: Book Rate
K59: =IF('Campaign Overview'!A3="","",'Campaign Overview'!A3) -> 3134980 | L59: =IF('Campaign Overview'!A3="","",'Campaign Overview'!B3) -> 60 Day Ads - Bathroom Renovations (USA) | M59: =IF('Campaign Overview'!A3="","",COUNTIFS('Raw SmartLead Replies'!A:A,'Campaign Overview'!A3,'Raw SmartLead Replies'!F:F,">="&TODAY()-30)) -> 0 | N59: =IF('Campaign Overview'!A3="","",COUNTIFS('Raw SmartLead Replies'!A:A,'Campaign Overview'!A3,'Raw SmartLead Replies'!G:G,"Interested",'Raw SmartLead Replies'!F:F,">="&TODAY()-30)) -> 0 | O59: =IF('Campaign Overview'!A3="","",COUNTIFS('Raw GHL Data'!C:C,'Campaign Overview'!A3,'Raw GHL Data'!E:E,">="&TODAY()-30)) -> 0 | P59: =IF('Campaign Overview'!A3="","",COUNTIFS('Raw GHL Data'!C:C,'Campaign Overview'!A3,'Raw GHL Data'!H:H,">="&TODAY()-30)) -> 0 | Q59: =IF(OR('Campaign Overview'!A3="",M59=0),"",P59/M59)
K60: =IF('Campaign Overview'!A4="","",'Campaign Overview'!A4) -> 3134858 | L60: =IF('Campaign Overview'!A4="","",'Campaign Overview'!B4) -> 60 Day Ads - General Construction USA (Tulsa, Tampa, Cincinnati) | M60: =IF('Campaign Overview'!A4="","",COUNTIFS('Raw SmartLead Replies'!A:A,'Campaign Overview'!A4,'Raw SmartLead Replies'!F:F,">="&TODAY()-30)) -> 0 | N60: =IF('Campaign Overview'!A4="","",COUNTIFS('Raw SmartLead Replies'!A:A,'Campaign Overview'!A4,'Raw SmartLead Replies'!G:G,"Interested",'Raw SmartLead Replies'!F:F,">="&TODAY()-30)) -> 0 | O60: =IF('Campaign Overview'!A4="","",COUNTIFS('Raw GHL Data'!C:C,'Campaign Overview'!A4,'Raw GHL Data'!E:E,">="&TODAY()-30)) -> 0 | P60: =IF('Campaign Overview'!A4="","",COUNTIFS('Raw GHL Data'!C:C,'Campaign Overview'!A4,'Raw GHL Data'!H:H,">="&TODAY()-30)) -> 0 | Q60: =IF(OR('Campaign Overview'!A4="",M60=0),"",P60/M60)
K61: =IF('Campaign Overview'!A5="","",'Campaign Overview'!A5) -> 3072412 | L61: =IF('Campaign Overview'!A5="","",'Campaign Overview'!B5) -> 60 Day Ads - Kitchen Renovators (USA) | M61: =IF('Campaign Overview'!A5="","",COUNTIFS('Raw SmartLead Replies'!A:A,'Campaign Overview'!A5,'Raw SmartLead Replies'!F:F,">="&TODAY()-30)) -> 0 | N61: =IF('Campaign Overview'!A5="","",COUNTIFS('Raw SmartLead Replies'!A:A,'Campaign Overview'!A5,'Raw SmartLead Replies'!G:G,"Interested",'Raw SmartLead Replies'!F:F,">="&TODAY()-30)) -> 0 | O61: =IF('Campaign Overview'!A5="","",COUNTIFS('Raw GHL Data'!C:C,'Campaign Overview'!A5,'Raw GHL Data'!E:E,">="&TODAY()-30)) -> 0 | P61: =IF('Campaign Overview'!A5="","",COUNTIFS('Raw GHL Data'!C:C,'Campaign Overview'!A5,'Raw GHL Data'!H:H,">="&TODAY()-30)) -> 0 | Q61: =IF(OR('Campaign Overview'!A5="",M61=0),"",P61/M61)
K62: =IF('Campaign Overview'!A6="","",'Campaign Overview'!A6) -> 3043415 | L62: =IF('Campaign Overview'!A6="","",'Campaign Overview'!B6) -> 60 Day Ads Offer - USA (LA, Detroit, Colorado Springs) - copy | M62: =IF('Campaign Overview'!A6="","",COUNTIFS('Raw SmartLead Replies'!A:A,'Campaign Overview'!A6,'Raw SmartLead Replies'!F:F,">="&TODAY()-30)) -> 0 | N62: =IF('Campaign Overview'!A6="","",COUNTIFS('Raw SmartLead Replies'!A:A,'Campaign Overview'!A6,'Raw SmartLead Replies'!G:G,"Interested",'Raw SmartLead Replies'!F:F,">="&TODAY()-30)) -> 0 | O62: =IF('Campaign Overview'!A6="","",COUNTIFS('Raw GHL Data'!C:C,'Campaign Overview'!A6,'Raw GHL Data'!E:E,">="&TODAY()-30)) -> 0 | P62: =IF('Campaign Overview'!A6="","",COUNTIFS('Raw GHL Data'!C:C,'Campaign Overview'!A6,'Raw GHL Data'!H:H,">="&TODAY()-30)) -> 0 | Q62: =IF(OR('Campaign Overview'!A6="",M62=0),"",P62/M62)
K63: =IF('Campaign Overview'!A7="","",'Campaign Overview'!A7) -> 2978732 | L63: =IF('Campaign Overview'!A7="","",'Campaign Overview'!B7) -> Huge USA Lead List - 60 Day Ads Offer (Xander) | M63: =IF('Campaign Overview'!A7="","",COUNTIFS('Raw SmartLead Replies'!A:A,'Campaign Overview'!A7,'Raw SmartLead Replies'!F:F,">="&TODAY()-30)) -> 0 | N63: =IF('Campaign Overview'!A7="","",COUNTIFS('Raw SmartLead Replies'!A:A,'Campaign Overview'!A7,'Raw SmartLead Replies'!G:G,"Interested",'Raw SmartLead Replies'!F:F,">="&TODAY()-30)) -> 0 | O63: =IF('Campaign Overview'!A7="","",COUNTIFS('Raw GHL Data'!C:C,'Campaign Overview'!A7,'Raw GHL Data'!E:E,">="&TODAY()-30)) -> 0 | P63: =IF('Campaign Overview'!A7="","",COUNTIFS('Raw GHL Data'!C:C,'Campaign Overview'!A7,'Raw GHL Data'!H:H,">="&TODAY()-30)) -> 0 | Q63: =IF(OR('Campaign Overview'!A7="",M63=0),"",P63/M63)
K64: =IF('Campaign Overview'!A8="","",'Campaign Overview'!A8) | L64: =IF('Campaign Overview'!A8="","",'Campaign Overview'!B8) | M64: =IF('Campaign Overview'!A8="","",COUNTIFS('Raw SmartLead Replies'!A:A,'Campaign Overview'!A8,'Raw SmartLead Replies'!F:F,">="&TODAY()-30)) | N64: =IF('Campaign Overview'!A8="","",COUNTIFS('Raw SmartLead Replies'!A:A,'Campaign Overview'!A8,'Raw SmartLead Replies'!G:G,"Interested",'Raw SmartLead Replies'!F:F,">="&TODAY()-30)) | O64: =IF('Campaign Overview'!A8="","",COUNTIFS('Raw GHL Data'!C:C,'Campaign Overview'!A8,'Raw GHL Data'!E:E,">="&TODAY()-30)) | P64: =IF('Campaign Overview'!A8="","",COUNTIFS('Raw GHL Data'!C:C,'Campaign Overview'!A8,'Raw GHL Data'!H:H,">="&TODAY()-30)) | Q64: =IF(OR('Campaign Overview'!A8="",M64=0),"",P64/M64)
K65: =IF('Campaign Overview'!A9="","",'Campaign Overview'!A9) | L65: =IF('Campaign Overview'!A9="","",'Campaign Overview'!B9) | M65: =IF('Campaign Overview'!A9="","",COUNTIFS('Raw SmartLead Replies'!A:A,'Campaign Overview'!A9,'Raw SmartLead Replies'!F:F,">="&TODAY()-30)) | N65: =IF('Campaign Overview'!A9="","",COUNTIFS('Raw SmartLead Replies'!A:A,'Campaign Overview'!A9,'Raw SmartLead Replies'!G:G,"Interested",'Raw SmartLead Replies'!F:F,">="&TODAY()-30)) | O65: =IF('Campaign Overview'!A9="","",COUNTIFS('Raw GHL Data'!C:C,'Campaign Overview'!A9,'Raw GHL Data'!E:E,">="&TODAY()-30)) | P65: =IF('Campaign Overview'!A9="","",COUNTIFS('Raw GHL Data'!C:C,'Campaign Overview'!A9,'Raw GHL Data'!H:H,">="&TODAY()-30)) | Q65: =IF(OR('Campaign Overview'!A9="",M65=0),"",P65/M65)
K66: =IF('Campaign Overview'!A10="","",'Campaign Overview'!A10) | L66: =IF('Campaign Overview'!A10="","",'Campaign Overview'!B10) | M66: =IF('Campaign Overview'!A10="","",COUNTIFS('Raw SmartLead Replies'!A:A,'Campaign Overview'!A10,'Raw SmartLead Replies'!F:F,">="&TODAY()-30)) | N66: =IF('Campaign Overview'!A10="","",COUNTIFS('Raw SmartLead Replies'!A:A,'Campaign Overview'!A10,'Raw SmartLead Replies'!G:G,"Interested",'Raw SmartLead Replies'!F:F,">="&TODAY()-30)) | O66: =IF('Campaign Overview'!A10="","",COUNTIFS('Raw GHL Data'!C:C,'Campaign Overview'!A10,'Raw GHL Data'!E:E,">="&TODAY()-30)) | P66: =IF('Campaign Overview'!A10="","",COUNTIFS('Raw GHL Data'!C:C,'Campaign Overview'!A10,'Raw GHL Data'!H:H,">="&TODAY()-30)) | Q66: =IF(OR('Campaign Overview'!A10="",M66=0),"",P66/M66)
K67: =IF('Campaign Overview'!A11="","",'Campaign Overview'!A11) | L67: =IF('Campaign Overview'!A11="","",'Campaign Overview'!B11) | M67: =IF('Campaign Overview'!A11="","",COUNTIFS('Raw SmartLead Replies'!A:A,'Campaign Overview'!A11,'Raw SmartLead Replies'!F:F,">="&TODAY()-30)) | N67: =IF('Campaign Overview'!A11="","",COUNTIFS('Raw SmartLead Replies'!A:A,'Campaign Overview'!A11,'Raw SmartLead Replies'!G:G,"Interested",'Raw SmartLead Replies'!F:F,">="&TODAY()-30)) | O67: =IF('Campaign Overview'!A11="","",COUNTIFS('Raw GHL Data'!C:C,'Campaign Overview'!A11,'Raw GHL Data'!E:E,">="&TODAY()-30)) | P67: =IF('Campaign Overview'!A11="","",COUNTIFS('Raw GHL Data'!C:C,'Campaign Overview'!A11,'Raw GHL Data'!H:H,">="&TODAY()-30)) | Q67: =IF(OR('Campaign Overview'!A11="",M67=0),"",P67/M67)
K68: =IF('Campaign Overview'!A12="","",'Campaign Overview'!A12) | L68: =IF('Campaign Overview'!A12="","",'Campaign Overview'!B12) | M68: =IF('Campaign Overview'!A12="","",COUNTIFS('Raw SmartLead Replies'!A:A,'Campaign Overview'!A12,'Raw SmartLead Replies'!F:F,">="&TODAY()-30)) | N68: =IF('Campaign Overview'!A12="","",COUNTIFS('Raw SmartLead Replies'!A:A,'Campaign Overview'!A12,'Raw SmartLead Replies'!G:G,"Interested",'Raw SmartLead Replies'!F:F,">="&TODAY()-30)) | O68: =IF('Campaign Overview'!A12="","",COUNTIFS('Raw GHL Data'!C:C,'Campaign Overview'!A12,'Raw GHL Data'!E:E,">="&TODAY()-30)) | P68: =IF('Campaign Overview'!A12="","",COUNTIFS('Raw GHL Data'!C:C,'Campaign Overview'!A12,'Raw GHL Data'!H:H,">="&TODAY()-30)) | Q68: =IF(OR('Campaign Overview'!A12="",M68=0),"",P68/M68)
K69: =IF('Campaign Overview'!A13="","",'Campaign Overview'!A13) | L69: =IF('Campaign Overview'!A13="","",'Campaign Overview'!B13) | M69: =IF('Campaign Overview'!A13="","",COUNTIFS('Raw SmartLead Replies'!A:A,'Campaign Overview'!A13,'Raw SmartLead Replies'!F:F,">="&TODAY()-30)) | N69: =IF('Campaign Overview'!A13="","",COUNTIFS('Raw SmartLead Replies'!A:A,'Campaign Overview'!A13,'Raw SmartLead Replies'!G:G,"Interested",'Raw SmartLead Replies'!F:F,">="&TODAY()-30)) | O69: =IF('Campaign Overview'!A13="","",COUNTIFS('Raw GHL Data'!C:C,'Campaign Overview'!A13,'Raw GHL Data'!E:E,">="&TODAY()-30)) | P69: =IF('Campaign Overview'!A13="","",COUNTIFS('Raw GHL Data'!C:C,'Campaign Overview'!A13,'Raw GHL Data'!H:H,">="&TODAY()-30)) | Q69: =IF(OR('Campaign Overview'!A13="",M69=0),"",P69/M69)
K70: =IF('Campaign Overview'!A14="","",'Campaign Overview'!A14) | L70: =IF('Campaign Overview'!A14="","",'Campaign Overview'!B14) | M70: =IF('Campaign Overview'!A14="","",COUNTIFS('Raw SmartLead Replies'!A:A,'Campaign Overview'!A14,'Raw SmartLead Replies'!F:F,">="&TODAY()-30)) | N70: =IF('Campaign Overview'!A14="","",COUNTIFS('Raw SmartLead Replies'!A:A,'Campaign Overview'!A14,'Raw SmartLead Replies'!G:G,"Interested",'Raw SmartLead Replies'!F:F,">="&TODAY()-30)) | O70: =IF('Campaign Overview'!A14="","",COUNTIFS('Raw GHL Data'!C:C,'Campaign Overview'!A14,'Raw GHL Data'!E:E,">="&TODAY()-30)) | P70: =IF('Campaign Overview'!A14="","",COUNTIFS('Raw GHL Data'!C:C,'Campaign Overview'!A14,'Raw GHL Data'!H:H,">="&TODAY()-30)) | Q70: =IF(OR('Campaign Overview'!A14="",M70=0),"",P70/M70)
... K107: =IF('Campaign Overview'!A51="","",'Campaign Overview'!A51) | L107: =IF('Campaign Overview'!A51="","",'Campaign Overview'!B51) | M107: =IF('Campaign Overview'!A51="","",COUNTIFS('Raw SmartLead Replies'!A:A,'Campaign Overview'!A51,'Raw SmartLead Replies'!F:F,">="&TODAY()-30)) | N107: =IF('Campaign Overview'!A51="","",COUNTIFS('Raw SmartLead Replies'!A:A,'Campaign Overview'!A51,'Raw SmartLead Replies'!G:G,"Interested",'Raw SmartLead Replies'!F:F,">="&TODAY()-30)) | O107: =IF('Campaign Overview'!A51="","",COUNTIFS('Raw GHL Data'!C:C,'Campaign Overview'!A51,'Raw GHL Data'!E:E,">="&TODAY()-30)) | P107: =IF('Campaign Overview'!A51="","",COUNTIFS('Raw GHL Data'!C:C,'Campaign Overview'!A51,'Raw GHL Data'!H:H,">="&TODAY()-30)) | Q107: =IF(OR('Campaign Overview'!A51="",M107=0),"",P107/M107)
A108: Past 90 Days | K108: =IF('Campaign Overview'!A52="","",'Campaign Overview'!A52) | L108: =IF('Campaign Overview'!A52="","",'Campaign Overview'!B52) | M108: =IF('Campaign Overview'!A52="","",COUNTIFS('Raw SmartLead Replies'!A:A,'Campaign Overview'!A52,'Raw SmartLead Replies'!F:F,">="&TODAY()-30)) | N108: =IF('Campaign Overview'!A52="","",COUNTIFS('Raw SmartLead Replies'!A:A,'Campaign Overview'!A52,'Raw SmartLead Replies'!G:G,"Interested",'Raw SmartLead Replies'!F:F,">="&TODAY()-30)) | O108: =IF('Campaign Overview'!A52="","",COUNTIFS('Raw GHL Data'!C:C,'Campaign Overview'!A52,'Raw GHL Data'!E:E,">="&TODAY()-30)) | P108: =IF('Campaign Overview'!A52="","",COUNTIFS('Raw GHL Data'!C:C,'Campaign Overview'!A52,'Raw GHL Data'!H:H,">="&TODAY()-30)) | Q108: =IF(OR('Campaign Overview'!A52="",M108=0),"",P108/M108)
A109: Time Range | B109: Campaign ID | C109: Campaign Name | D109: Total Replied | E109: Positive Replies | F109: Call Proposed | G109: Call Booked | H109: Book Rate | K109: =IF('Campaign Overview'!A53="","",'Campaign Overview'!A53) | L109: =IF('Campaign Overview'!A53="","",'Campaign Overview'!B53) | M109: =IF('Campaign Overview'!A53="","",COUNTIFS('Raw SmartLead Replies'!A:A,'Campaign Overview'!A53,'Raw SmartLead Replies'!F:F,">="&TODAY()-30)) | N109: =IF('Campaign Overview'!A53="","",COUNTIFS('Raw SmartLead Replies'!A:A,'Campaign Overview'!A53,'Raw SmartLead Replies'!G:G,"Interested",'Raw SmartLead Replies'!F:F,">="&TODAY()-30)) | O109: =IF('Campaign Overview'!A53="","",COUNTIFS('Raw GHL Data'!C:C,'Campaign Overview'!A53,'Raw GHL Data'!E:E,">="&TODAY()-30)) | P109: =IF('Campaign Overview'!A53="","",COUNTIFS('Raw GHL Data'!C:C,'Campaign Overview'!A53,'Raw GHL Data'!H:H,">="&TODAY()-30)) | Q109: =IF(OR('Campaign Overview'!A53="",M109=0),"",P109/M109)
A110: =IFERROR(arrayformula(IF(LEN(B110:B359),"Past 90 Days","")),"") | B110: =IFERROR(filter({K111:K360,L111:L360,M111:M360,N111:N360,O111:O360,P111:P360,Q111:Q360},M111:M360>0,K111:K360<>""),"(no campaigns with activity in this period)") -> #N/A | K110: Campaign ID | L110: Campaign Name | M110: Total Replied | N110: Positive Replies | O110: Call Proposed | P110: Call Booked | Q110: Book Rate
K111: =IF('Campaign Overview'!A3="","",'Campaign Overview'!A3) -> 3134980 | L111: =IF('Campaign Overview'!A3="","",'Campaign Overview'!B3) -> 60 Day Ads - Bathroom Renovations (USA) | M111: =IF('Campaign Overview'!A3="","",COUNTIFS('Raw SmartLead Replies'!A:A,'Campaign Overview'!A3,'Raw SmartLead Replies'!F:F,">="&TODAY()-90)) -> 0 | N111: =IF('Campaign Overview'!A3="","",COUNTIFS('Raw SmartLead Replies'!A:A,'Campaign Overview'!A3,'Raw SmartLead Replies'!G:G,"Interested",'Raw SmartLead Replies'!F:F,">="&TODAY()-90)) -> 0 | O111: =IF('Campaign Overview'!A3="","",COUNTIFS('Raw GHL Data'!C:C,'Campaign Overview'!A3,'Raw GHL Data'!E:E,">="&TODAY()-90)) -> 0 | P111: =IF('Campaign Overview'!A3="","",COUNTIFS('Raw GHL Data'!C:C,'Campaign Overview'!A3,'Raw GHL Data'!H:H,">="&TODAY()-90)) -> 0 | Q111: =IF(OR('Campaign Overview'!A3="",M111=0),"",P111/M111)
K112: =IF('Campaign Overview'!A4="","",'Campaign Overview'!A4) -> 3134858 | L112: =IF('Campaign Overview'!A4="","",'Campaign Overview'!B4) -> 60 Day Ads - General Construction USA (Tulsa, Tampa, Cincinnati) | M112: =IF('Campaign Overview'!A4="","",COUNTIFS('Raw SmartLead Replies'!A:A,'Campaign Overview'!A4,'Raw SmartLead Replies'!F:F,">="&TODAY()-90)) -> 0 | N112: =IF('Campaign Overview'!A4="","",COUNTIFS('Raw SmartLead Replies'!A:A,'Campaign Overview'!A4,'Raw SmartLead Replies'!G:G,"Interested",'Raw SmartLead Replies'!F:F,">="&TODAY()-90)) -> 0 | O112: =IF('Campaign Overview'!A4="","",COUNTIFS('Raw GHL Data'!C:C,'Campaign Overview'!A4,'Raw GHL Data'!E:E,">="&TODAY()-90)) -> 0 | P112: =IF('Campaign Overview'!A4="","",COUNTIFS('Raw GHL Data'!C:C,'Campaign Overview'!A4,'Raw GHL Data'!H:H,">="&TODAY()-90)) -> 0 | Q112: =IF(OR('Campaign Overview'!A4="",M112=0),"",P112/M112)
K113: =IF('Campaign Overview'!A5="","",'Campaign Overview'!A5) -> 3072412 | L113: =IF('Campaign Overview'!A5="","",'Campaign Overview'!B5) -> 60 Day Ads - Kitchen Renovators (USA) | M113: =IF('Campaign Overview'!A5="","",COUNTIFS('Raw SmartLead Replies'!A:A,'Campaign Overview'!A5,'Raw SmartLead Replies'!F:F,">="&TODAY()-90)) -> 0 | N113: =IF('Campaign Overview'!A5="","",COUNTIFS('Raw SmartLead Replies'!A:A,'Campaign Overview'!A5,'Raw SmartLead Replies'!G:G,"Interested",'Raw SmartLead Replies'!F:F,">="&TODAY()-90)) -> 0 | O113: =IF('Campaign Overview'!A5="","",COUNTIFS('Raw GHL Data'!C:C,'Campaign Overview'!A5,'Raw GHL Data'!E:E,">="&TODAY()-90)) -> 0 | P113: =IF('Campaign Overview'!A5="","",COUNTIFS('Raw GHL Data'!C:C,'Campaign Overview'!A5,'Raw GHL Data'!H:H,">="&TODAY()-90)) -> 0 | Q113: =IF(OR('Campaign Overview'!A5="",M113=0),"",P113/M113)
...
